<?xml version="1.0" ?>
<robot name="robot" xmlns:xacro="http://ros.org/wiki/xacro">
  
  <!-- include the xacro files--> 
  <xacro:include filename="$(find learnbotics)/urdf/robot.gazebo"/>
  <xacro:include filename="$(find learnbotics)/urdf/velodyne.xacro"/>
  <xacro:include filename="$(find learnbotics)/urdf/camera.xacro"/>

  <link name="base_link">

  </link>

  <link name="capa">
    <inertial>
      <mass value="0.327"/>
      <origin rpy="0  0  0" xyz="0  0  0"/>
      <inertia ixx="0.001029" ixy="0" ixz="0" iyy="0.0006633" iyz="0" izz="0.001202"/>
    </inertial>
    <collision name="robot__collision">
      <origin rpy="0      0      1.5707" xyz="0  0  0"/>
      <geometry>
        <mesh filename="package://learnbotics/meshes/capa.stl" scale="1 1 1"/>
      </geometry>
    </collision>
    <visual name="robot__visual">
      <origin rpy="0      0      1.5707" xyz="0  0  0"/>
      <geometry>
        <mesh filename="package://learnbotics/meshes/capa.stl" scale="1 1 1"/>
      </geometry>
    </visual>
  </link>
  <joint name="base_to_capa" type="fixed">
    <parent link="base_link"/>
    <child link="capa"/>
    <origin rpy="0 0 0" xyz="0.0 0.0 0.0"/>
  </joint>

  <link name="wheel_right">
    <inertial>
      <mass value="0.027"/>
      <origin rpy="0  0  0" xyz="0  0  0"/>
      <inertia ixx="1.905e-05" ixy="0" ixz="0" iyy="1.905e-05" iyz="0" izz="2.138e-05"/>
    </inertial>
    <collision name="robot__collision">
      <origin rpy="0  0  0" xyz="0  0  0"/>
      <geometry>
        <mesh filename="package://learnbotics/meshes/wheel.stl" scale="1 1 1"/>
      </geometry>
    </collision>
    <visual name="robot__visual">
      <origin rpy="0  0  0" xyz="0  0  0"/>
      <geometry>
        <mesh filename="package://learnbotics/meshes/wheel.stl" scale="1 1 1"/>
      </geometry>
    </visual>
  </link>
  <joint name="capa_JOINT_wheel_right" type="continuous">
    <parent link="capa"/>
    <child link="wheel_right"/>
    <origin rpy="1.5707  0      0" xyz="-0.05502 -0.05936 -0.02971"/>
    <axis xyz="0   0  1"/>
    <limit effort="-1.0" lower="-1.79769e+308" upper="1.79769e+308" velocity="-1.0"/>
  </joint>

  <link name="wheel_left">
    <inertial>
      <mass value="0.027"/>
      <origin rpy="0  0  0" xyz="0  0  0"/>
      <inertia ixx="1.905e-05" ixy="0" ixz="0" iyy="1.905e-05" iyz="0" izz="2.138e-05"/>
    </inertial>
    <collision name="robot__collision">
      <origin rpy="3.14159000e+00   1.59000000e-03   3.14159000e+00" xyz="0  0  0"/>
      <geometry>
        <mesh filename="package://learnbotics/meshes/wheel.stl" scale="1 1 1"/>
      </geometry>
    </collision>
    <visual name="robot__visual">
      <origin rpy="3.14159000e+00   1.59000000e-03   3.14159000e+00" xyz="0  0  0"/>
      <geometry>
        <mesh filename="package://learnbotics/meshes/wheel.stl" scale="1 1 1"/>
      </geometry>
    </visual>
  </link>
  <joint name="capa_JOINT_wheel_left" type="continuous">
    <parent link="capa"/>
    <child link="wheel_left"/>
    <origin rpy="1.5707  0      0" xyz="-0.05559  0.05972 -0.02971"/>
    <axis xyz="0 0 1"/>
    <limit effort="-1.0" lower="-1.79769e+308" upper="1.79769e+308" velocity="-1.0"/>
  </joint>

  <link name="ball">
    <inertial>
      <mass value="0.004"/>
      <origin rpy="0  0  0" xyz="0  0  0"/>
      <inertia ixx="1.7e-07" ixy="0" ixz="0" iyy="1.7e-07" iyz="0" izz="1.7e-07"/>
    </inertial>
    <collision name="robot__collision">
      <origin rpy="0  0  0" xyz="0  0  0"/>
      <geometry>
        <mesh filename="package://learnbotics/meshes/bol.stl" scale="1 1 1"/>
      </geometry>
    </collision>
    <visual name="robot__visual">
      <origin rpy="0  0  0" xyz="0  0  0"/>
      <geometry>
        <mesh filename="package://learnbotics/meshes/bol.stl" scale="1 1 1"/>
      </geometry>
    </visual>
  </link>
  <joint name="capa_JOINT_ball" type="continuous">
    <parent link="capa"/>
    <child link="ball"/>
    <origin rpy="0  0  0" xyz="0.02828  0      -0.065"/>
    <axis xyz="1  1  1"/>
    <limit effort="0" lower="0" upper="0" velocity="0"/>
  </joint>

  <joint name="capa_JOINT_base_lidar" type="fixed">
    <origin xyz="0.0 0.0 0.06" rpy="0.0 0.0 3.14"/>
    <parent link="capa"/>
    <child link="base_lidar"/>
  </joint>

  <joint name="capa_JOINT_base_camera" type="fixed">
    <origin xyz="0.08 0.0 0.03" rpy="0.0 0.0 0.0"/>
    <parent link="capa"/>
    <child link="base_camera"/>
  </joint>
</robot>
